Workbook
Name GRN人数: #REF!
Name ああああ: #REF!
Name その他: #REF!
Name 一般人数: #REF!
Name 運搬費: #REF!
Name 演奏料: #REF!
Name 応募分野: #REF!
Name 応募分野: #REF!
Name 会場費: #REF!
Name 会場費: #REF!
Name 会場費・舞台費・運搬費: #REF!
Name 会場費・舞台費・運搬費: #REF!
Name 感染症対策経費: #REF!
Name 感染症対策経費: #REF!
Name 記録作成: #REF!
Name 稽古費: #REF!
Name 稽古費: #REF!
Name 後継者養成: #REF!
Name 交通費GRN: #REF!
Name 交通費一般: #REF!
Name 参照データ: #REF!
Name 事務経費: #REF!
Name 謝金・旅費・宣伝費等: #REF!
Name 謝金・旅費・宣伝費等: #REF!
Name 出演費・音楽費・文芸費: #REF!
Name 出演費・音楽費・文芸費: #REF!
Name 巡回運搬賃１: #REF!
Name 巡回運搬賃２: #REF!
Name 助成対象外経費: #REF!
Name 助成対象外経費: #REF!
Name 情報発信: #REF!
Name 人材育成: #REF!
Name 世界文化遺産活性化: #REF!
Name 宣伝費: #REF!
Name 地域の文化資源を核としたコミュニティの再生・活性化: #REF!
Name 地域の文化資源を活用した集客・交流: #REF!
Name 地域文化遺産活性化: #REF!
Name 伝統文化の継承体制の維持・確立: #REF!
Name 俳優出演料: #REF!
Name 普及啓発: #REF!
Name 舞台費: #REF!
Name 舞台費: #REF!
Name 用具等整備: #REF!
Name 旅費: #REF!
Name 旅費: #REF!
Name 練習会場費: #REF!

Sheet 表紙
D3: 文化芸術活動基盤強化基金
C4: クエリエイター等育成支援 コンテンツ制作・発信を支える中核的専門人材育成・確保等
C5: 【補助型】
D6: 助 成 金 交 付 要 望 書
N8: 令和８年 月 日
B10: 独立行政法人日本芸術文化振興会理事長 殿
H12: （申請者）
H14: 団 体 名 | K14: デジタルハリウッド株式会社
J16: 〒 | K16: 〒101-0062
H17: 住所（所在地） | K17: 東京都千代田区神田駿河台4-6 御茶ノ水ソラシティ アカデミア 4F
H19: 代表者の職名・氏名 | K19: 代表取締役社長兼CEO 藤井雅徳
C22: 下記の事業を行いたいので、文化芸術活動基盤強化基金助成金交付要綱第３条に基づき、助成金の交付を要望します。
C24: 記
C27: １．プロジェクト名 プロジェクト名は採択時の公表資料に 掲載されますのでご留意ください | H27: AI・バーチャルプロダクションを活用した3DCG制作人材育成事業 ─ AI時代の3DCG制作フロー高度化を担う中核人材の育成 ─ | V27: 単願
C28: ２．実 施 期 間 | H28: 交付内定日～令和１１年３月３１日
C29: ３．対 象 分 野 | H29: 映像
C30: 「その他」の場合、右欄に当該分野名を記載してください
C31: ４．要 望 額 | H31: ='１０．収支予算書'!C30 -> 191318 | O31: 千円
C33: 【責任者・担当者連絡先】
C34: 事業責任者 | F34: 所属・職名 | G34: デジタルハリウッド大学 学長 | K34: 電話 | M34: 【要記入：電話】
F35: フリガナ | G35: フジイ ナオタカ | K35: メールアドレス | M35: 【要記入：メール】
F36: 氏名 | G36: 藤井 直敬
C37: 経理責任者 | F37: 所属・職名 | G37: 【要記入：所属・職名】 | K37: 電話 | M37: 【要記入：電話】
F38: フリガナ | G38: 【要記入：フリガナ】 | K38: メールアドレス | M38: 【要記入：メール】
F39: 氏名 | G39: 【要記入：氏名】
C40: 事務担当者 | F40: 所属・職名 | G40: 【要記入：所属・職名】 | K40: 電話 | M40: 【要記入：電話】
F41: フリガナ | G41: 【要記入：フリガナ】 | K41: メールアドレス | M41: 【要記入：メール】
F42: 氏名 | G42: 【要記入：氏名】
C43: 資料の 送付先 | F43: 〒101-0062 東京都千代田区神田駿河台4-6 御茶ノ水ソラシティ アカデミア 4F
C46: ※連携先については「７．連携先」にご記載ください。
B48: ※ Ａ４判１枚に収まるように作成してください。

Sheet １．団体概要
B1: １．団体の概要 ※審査要領１．審査項目「① 組織」にも留意
B3: フリガナ | D3: デジタルハリウッドカブシキガイシャ
B4: 団体名 | D4: デジタルハリウッド株式会社（事業主体：デジタルハリウッド大学・大学院）
B5: 代表者役職名 | D5: 代表取締役社長兼CEO | I5: フリガナ | N5: フジイ マサノリ
I6: 代表者氏名 | N6: 藤井 雅徳
B7: 郵便番号 | D7: 101 | E7: ― | F7: 0062 | I7: 電話 | N7: 03-5289-9230
B8: 住所 | D8: 東京都千代田区神田駿河台4-6 御茶ノ水ソラシティ アカデミア 4F | I8: メールアドレス | N8: fujiimasanori@dhw.co.jp
I9: ウェブサイト | N9: https://www.dhw.ac.jp/
B10: 団体の種類 | D10: その他法人 | G10: 株式会社 | J10: [その他の法人の場合は括弧内に具体的な種類名を記入] | W10: 公益財団法人 | X10: 公益社団法人 | Y10: 一般財団法人 | Z10: 一般社団法人 | AA10: 認定特定非営利活動法人 | AB10: 特定非営利活動法人 | AC10: 株式会社 | AD10: 合同会社 | AE10: 有限会社 | AF10: その他法人
B11: 団体設立年月 | D11: 2005年4月 | G11: 法人設立年月 | J11: 1994年10月3日 | O11: 【法人番号13桁】
B12: 団体の体制 | D12: 役 職 員 | I12: 左記以外の構成員
D13: 【要記入：教員数〇名、職員数〇名（大学の体制を記入）】 | I13: 【要記入：左記以外の構成員】
D14: 経理担当者 | F14: 経理担当者氏名
D15: 監査担当者 | F15: 監査担当者氏名
B16: 沿 革 | D16: 1994年10月デジタルハリウッド株式会社設立、デジタルハリウッドTHE MULTIMEDIA SCHOOLを開校（東京都千代田区）。2004年デジタルハリウッド大学院大学を開学（日本初の株式会社立専門職大学院）。2005年デジタルハリウッド大学を開学（株式会社立大学）。2010年・2018年大学基準協会／日本高等教育評価機構による大学機関別認証評価（適合）。2013年東京本校およびデジタルハリウッド大学を御茶ノ水ソラシティ アカデミアへ移転。2025年 主要株主が株式会社ベネッセホールディングスに交代。2026年4月 第2代学長として藤井直敬が就任（初代：杉山知之／2005-2026）。創設以来30年、累計9万人以上の卒業生・受講生を輩出。
B17: 設立の趣旨・目的、理念 | D17: 建学の精神「Entertainment. It's Everything.（すべてをエンタテインメントにせよ。）」のもと、デジタルテクノロジーを駆使してエンタテインメントを創造する人材を育成する。産業界と直結した実践型カリキュラム、現役実務家教員による教育、企業連携型PBL、社会人向けリスキリング支援を通じて、即戦力となるクリエイター・プロデューサーを継続的に輩出し、日本のコンテンツ産業の競争力強化と文化の発信に寄与することを目的とする。2026年4月就任の第2代学長 藤井直敬は「世界を満たせ。Fill the world.」を新たな合言葉として掲げ、AI時代に「主体的に定義し、創造する」人材育成を強化している。
B18: 過去の取組とその実績 | D18: 運営法人デジタルハリウッド株式会社（1994年設立）は累計9万人以上の卒業生・受講生を輩出してきた基盤を有する。本学（大学院2004年・大学2005年開学）は、現役実務家教員による実践型教育、企業連携型PBL、社会人向けリスキリング支援を通じて即戦力人材を業界に送出し、修了生は映像・アニメ・ゲーム・VFX・CG等で活躍。2024年に本学修了生作品が学生アカデミー賞アニメーション部門銀賞（日本作品初）を受賞、2025年に文部科学省MDASH（リテラシーレベルプラス）認定および経済産業省調査による大学発ベンチャー創出実績で全国15位（私立6位）。
B19: 直近の文化庁及び他省庁等の支援事業への応募 | E19: 名称 | I19: 申請額 | N19: 概要
D20: 1 | M20: 千円
D21: 2 | M21: 千円
D22: 3 | M22: 千円
B23: 財務状況 （単位：千円） | D23: 年度 | E23: 総収入 | G23: 総支出 | I23: 当期損益 | L23: 累積損益 | N23: 総収入のうち当該年度に受けた公的な補助金・助成金
N24: 金額 | O24: 名称
D25: R5
D26: R6 (見込)
D27: R7 (見込)
B28: ※ Ａ４判１枚に収まるように作成してください。

Sheet ２．自己申告書
B1: ２．団体の運営状況（自己申告書）
B3: ①定款等
C4: ○定款等を適切に定めている。 | K4: はい
B6: ②意思決定機関
C7: ○団体の意思等を決定する機関（理事会、取締役会等）を設置している。 | K7: はい
C8: ○理事会等を定期的に開催している。 | K8: はい
C9: ○理事会等の議事録を作成している。 | K9: はい
C10: ○事業計画及び予算並びに事業報告及び決算について理事会等の決議を経ている。 | K10: はい
C12: 以下は、理事会等を設置している場合のみ回答してください。
C13: ○理事会等の構成についてジェンダーバランスに配慮している。 | K13: はい
B15: ③運営事務
C16: ○経理責任者は明確になっている。 | K16: はい
C17: ○現預金の出納責任者は明確になっている。 | K17: はい
C18: ○銀行印の管理責任者は明確になっている。 | K18: はい
C19: ○事務の執行に当たっては、各担当者の権限と責任が明確になっている。 | K19: はい
C20: ○業者選定等に関する規程等を整備している。 | K20: はい
C21: ○予算執行に係る全ての証憑（契約書・領収書等）を善良な管理者の注意をもって５年間以上保管している。 | K21: はい
C22: ○利益相反取引を行っていない（適切な承認手続きを経たものを除く）。 | K22: はい
D23: ※利益相反行為とは、複数の当事者がいる場合における、一方の利益となり、かつ他方の不利益となる行為を指す。
C24: ○手許現金有高は、定期的に出納担当者以外の者が出納簿と照合している。 | K24: はい
C25: ○法人税や消費税、源泉所得税等で必要な申告義務を適切に実施している。 | K25: はい
B27: 財務
B28: ④財務諸表等
C29: ○会計帳簿（仕訳帳・総勘定元帳等）を作成している。 | K29: はい
C30: ○財務諸表（貸借対照表・損益計算書等）を作成している。 | K30: はい
C31: ○財務諸表（貸借対照表・損益計算書等）を公表している。 | K31: はい
D32: ※本項目における「公表」とは、ウェブサイトに掲載していること、もしくは事務所に備え付け一般からの 要望があれば常に閲覧することができる状態にしていることを指す。
B34: ⑤監査
C35: ○監事・監査役等による会計監査又はこれに準じた内部監査を実施している。 | K35: はい
C36: （「はい」の場合は当てはまるものにチェック）
D38: 外部監査（監査法人、公認会計士による会計監査）
D39: 内部監査（監事監査、監査役監査による会計監査）
D40: 内部監査に準じた監査（経理責任者による会計監査等）
C42: ○監事等による監査報告書を作成している。 | K42: はい
B44: 活動環境
B45: ⑥労務管理
C46: ○就業規則を明文化している。 | K46: はい
C47: ○労働基準法に則り、雇用者の労働時間・休憩・休日等を適切に管理している。 | K47: はい
C48: ○雇用契約書の取り交わし等、雇用者に対して書面により労働条件を明示している。 | K48: はい
C49: ○雇用者に対し、規則等で作品制作料・出演料等の単価を定めている。 | K49: はい
...

Sheet ３．全体計画、４．観点対応
B1: ３．プロジェクト全体の計画（３年間） ※審査要領１．審査項目「② プロジェクト内容」～「④ 将来性」にも留意
B3: ○ プロジェクトの概要 ※この概要は採択時の公表資料に掲載されますのでご留意ください。
B4: 生成AIとリアルタイム制作技術の急速な普及により、映像・VFX・3DCG・アニメ・ゲームの各分野で3DCG制作フローが共通基盤化しつつあり、従来の業界別人材育成ではAI時代の制作フローに対応しきれない。本事業は、産業を横断して活躍できる「3DCG制作中核人材」を3年間で累計1,080名（リテラシー600名・実践360名・高度120名）育成するものである。具体的には、2026年2月に稼働開始した本学のLEDウォールVP環境および国際的VFX教授陣を活用し、生成AI×バーチャルプロダクション×3DCGを統合した「AI Nativeワークフロー」を中核とする実践型プログラムを展開する。さらにベネッセAI教育研究所と共催で企業ゼミ（リテラシー〜実践）を運営し、修了生3年継続追跡によるEBPM評価および全国教育機関への成果展開を一体的に推進する。 | L4: ※枠内に収まるように400字程度で記載してください。
B6: 〇本プロジェクトの実施により、期待される成果や波及効果（我が国のコンテンツ制作現場を支える中核的専門人材の育成・確保、各分野の文化芸術活動の活性化、国際的プレゼンスの向上等）
B7: 直接成果として、3年間で1,080名の3DCG制作中核人材を育成し、中級・上級修了生（実践・高度の480名）について業界就業率70%以上、修了後3年継続従事率70%以上を実現する。加えて、教材公開・FD研修・出前授業・サマースクール等を通じて累計177団体（自治体15／中高75／高等教育機関45／各種学校42）へ育成モデルを展開し、全国的な人材育成基盤の拡充に寄与する。さらに業界標準コンピテンシーモデルおよび国産デジタルデザインプラットフォーム要件定義書を策定・公開し、業界団体（CESA・VFX-JAPAN等）・関係省庁（経産省・文化庁・内閣府）と共有し、政策・産業界が参照できる公共財として提供する。本事業は単一大学の取組を超え、AI時代の産業横断型3DCG制作人材育成モデルを日本で初めて構築するものであり、コンテンツ産業の国際競争力強化と文化芸術の国際的プレゼンス向上に資する。 | L7: ※枠内に収まるように400字程度で記載してください。
B9: ４．「プロジェクトに盛り込むべき観点」への対応
B11: ① マンガ、アニメ、ゲーム、映像（実写映画及びアニメーション映画）、音楽（ポピュラーミュージック関係）等の分野において、海外発信を見据えたコンテンツ制作の高品質化・需要増大に対して必要となる中核的専門人材（アニメーター（原画、動画、背景）、美術、撮影、編集、音響、ゲームプログラマー、ゲームデザイナー、３DCGクリエイター、ＶＦＸクリエイター、サウンドクリエイター、マンガ翻訳者等）を育成・確保するためのプロジェクトであること。
B12: 右記を最低１つ以上含む必要があります。該当する取組に「〇」を付してください。 | D12: 〇 | E12: 基本的技術の理解・習得 | G12: 〇 | H12: 新技術（3DCG、VFX、AI等）活用能力の育成
D13: 〇 | E13: 卓越した技術の継承 | G13: 〇 | H13: 当該職種での定着・キャリア選択の支援
B14: 本事業は、募集要領で例示された中核的専門人材（3DCGクリエイター・VFXクリエイター等）を、AI時代の産業横断型制作フローに対応する形へ発展させ、映像・VFX・3DCG・アニメ・ゲームの5分野にわたる制作中核人材を育成する。育成はリテラシー・実践・高度の3階層で構成し、生成AI（ChatGPT／Gemini／Claude等）と業界標準ツール群（Adobe／Figma／Canva／Blender／Unreal Engine）の体系学習で基本技術の習得を図るとともに、国際的VFX教授（エカート教授）によるFramestore流ワークフロー継承で卓越技術を継承する。さらにAI×LEDウォール統合ワークフロー設計能力の育成により新技術活用能力を高め、ベネッセAI教育研究所による業界マッチング・3年継続追跡でキャリア選択を支援する。これらを統合的に展開し、4観点すべてを充足する設計とする。 | L14: ※枠内に収まるように400字程度で記載してください。
B16: ② 本事業を通じて中核的専門人材の育成・確保の持続的な基盤を形成する観点から、単一の主体における人材育成にとどまらない、業界への就業（他業種からの流入も可）や定着が考慮されているプロジェクトであること。
B17: 本学（大学院2004年・大学2005年開学）は、運営法人デジタルハリウッド株式会社（1994年設立）を中核とするグループ累計9万人以上の輩出基盤を有し、修了生は各産業で活躍している。本事業ではこの基盤上に5分野（映像・VFX・3DCG・アニメ・ゲーム）の企業群（累計100社以上）とOJT・インターンシップ・実制作指導で連携し、修了生が特定業界に閉じない選択肢を持てる構造を実現する。定着検証はベネッセAI教育研究所による修了生3年継続追跡で行い、業界就業率（中級・上級修了生＝実践・高度の480名対象）70%以上、修了後3年継続従事率70%以上を目標とする。事業終了後は本事業で開発したカリキュラムを本学（大学・大学院）の正課授業として恒常的に組み込み、学費収入を財源として運営することで、継続的な育成基盤を確立する。 | L17: ※枠内に収まるように400字程度で記載してください。
B19: ③ 産業界のニーズを踏まえた中核的専門人材の育成・確保が必要であるため、当該コンテンツ分野において具体的な人材ニーズが現に存在する、または、ニーズが生じると見込まれる人材の育成・確保に取り組むプロジェクトであること。当該人材ニーズが定量的に計測できる場合はそれも記載するとともに、プロジェクトの実施によりどの程度不足の解消に貢献できるのかも記載。
B20: 人材ニーズは公的資料および業界データの双方から裏付けられている。経産省「エンタメ・クリエイティブ産業戦略」（2025年6月）は海外売上2033年20兆円を掲げる一方「クリエイター・ビジネス人材の不足」を明示し、同省「第8回エンタメ・クリエイティブ産業政策研究会」資料（2025年10月）でも、世界需要が拡大する中、アニメ・実写分野で「制作スタジオや人材の供給不足」が改めて指摘されている。業界データでも帝国データバンク「アニメ制作市場動向調査2025」で市場3,621億円と過去最高更新ながら元請60%が業績悪化し「利益なき繁忙」と分析される。国内VFX市場はIMARC Group調査で年平均成長率6.5%（2025-2033年）と継続成長が見込まれ、3DCG・VFXクリエイターは慢性的な人材不足にある。本事業はこれらに応え、1,080名を直接輩出し、177団体への波及により人材供給基盤の拡大に寄与する。 | L20: ※枠内に収まるように400字程度で記載してください。
B22: ④ プロジェクトを実施するに当たって適切な関係者・団体等と連携する計画となっており、それら連携先と事前協議を行っている又は行う計画であること。 （７．連携先、８．指導者等とも関係）
B23: 本事業は連携先ベネッセAI教育研究所との2者連携により補助型応募要件を満たす。同研究所は教育効果のEBPM評価機関であると同時に、教育モデルを全国の教育機関へ展開する社会実装プレイヤーでもあり、本事業の中核連携先として最適である。事前協議は既に実施済みであり、令和8年度第1四半期に正式協定を締結する。同研究所が担う役割は、①本学との共催による企業ゼミ（リテラシー〜実践）の設計・運営と受講生事前事後アセスメント、②修了生3年継続追跡、③EBPM評価・要因分析、④研究レポート共同編集、⑤全国教育機関への教育モデル展開支援、⑥高大接続設計、⑦オンラインプラットフォームによる普及、の7点である。加えて事業実施を通じて、業界横断連携（5分野の企業群・累計100社以上）、教育波及連携（累計177団体）、行政・産業共有（経産省・文化庁・CESA・VFX-JAPAN等）へ段階的に連携を拡大する。 | L23: ※枠内に収まるように400字程度で記載してください。
B24: ※ Ａ４判１枚に収まるように作成してください。

Sheet ５．プロジェクト詳細
B1: ５．プロジェクトの詳細
B3: 実施方針及び実施計画・スケジュール等の決定 ※「求める要件」（１）参照、６．スケジュール詳細にも関係
B4: 〔具体的な取組内容〕
B5: 【実施方針】 産業横断型3DCG制作中核人材の育成を、リテラシー・実践・高度の3階層で実施する。リテラシーコース（年200名）では3DCG・AI・VPの基礎を共通基盤として全員が習得し、実践コース（年120名）では本人の希望と適性に応じて映像・VFX・3DCG・アニメ・ゲームの5分野いずれかの専門領域に分化する。さらに高度コース（年40名）は実践修了者から選抜のうえ、VP・リアルタイムCGの高度専門能力を養成する。 【決定プロセス】 令和8年度第1〜第2四半期にエカート教授との統合設計によるカリキュラム共同開発、AI・VPスキル標準の策定、各コース第1期向け教材開発を実施する。第3四半期からは3階層の同時開講に移行し、LEDウォール環境を活用した産業横断型実制作演習を本格稼働させるとともに、エカート教授による上級指導を開始する。 【AI Nativeワークフロー】 3DCG制作工程を「①企画・開発、②プリプロダクション、③バーチャルプロダクション、④ポストプロダクション、⑤検証・アーカイブ」の5段階に再設計し、各段階でAI・リアルタイム制作・VPを統合的に活用する。
B11: 事務局の設置と実施体制の明確化 ※「求める要件」（２）参照
B12: 〔具体的な取組内容〕
B13: 【事務局】 専従事務局をデジタルハリウッド大学内に設置し、専従スタッフ（プログラム・ディレクター、教務担当、広報担当、経理担当）を配置のうえ、年度ごとの執行計画と実績管理を行う。実施期間中は、振興会および文化庁と定期的に協議の場を設け、必要な連絡・事務を執り行う。 【実施体制】 事業責任者は学長・藤井直敬が務め、本学が中核実施機関として、教育設計・運営・成果評価・修了生支援を一貫して実施する。中核指導者には、クリストファー・ハンス・エカート教授を招聘済。育成対象者については、修了後もベネッセAI教育研究所との連携により3年継続追跡を行い、振興会・文化庁からの求めに応じて速やかに活動状況を報告できる体制を整える。 【連携先】 ベネッセAI教育研究所が本学との共催による企業ゼミ（リテラシー〜実践）の設計・運営を担うとともに、教育効果測定・修了生追跡・EBPM評価・全国教育機関展開支援・高大接続設計・オンライン普及までを一体的に担当する。
B19: 広報等の実施及び成果発表 ※「求める要件」（３）参照
B20: 〔具体的な取組内容〕
B21: 【広報】 特設Webサイト・SNS・大学広報を通じて受講生募集と事業情報を発信するとともに、業界専門メディア（CGWORLDほか）への寄稿・掲載を行う。あわせて年次研究会を開催する（年4回×3年、延べ参加者1,500名以上）。 【成果発表】 中間研究レポート（令和8年度末・令和9年度末）および最終研究レポート（令和10年度末）を公開し、実制作作品（3年累計24作品以上）の発表会を開催する。令和10年度第3四半期にプロジェクト成果をネットやSNSで発信するとともに、国際カンファレンスを通して海外に広く周知する。 【モデル展開】 教材公開ライセンス（累計50本以上）、FD研修（年2回・累計150名以上）、出前授業、サマースクール（累計修了者120名以上＝年40名×3年）等の取組を通じて、累計177団体（自治体15／中高75／高等教育機関45／各種学校42）へモデルを展開する。 【業界・行政共有】 業界標準コンピテンシーモデルおよび国産デジタルデザインプラットフォーム要件定義書を策定・公開し、経済産業省・文化庁・内閣府への報告および業界団体（CESA・VFX-JAPAN等）への共有を実施するとともに、関連研究会を累計3回以上開催する。
B26: ※ Ａ４判１枚に収まるように作成してください。

Sheet ６．スケジュール詳細
B1: ６．スケジュール詳細 ※「求める要件」（１）参照
B2: 職 種 | C2: １年目 令和8年度（2026年度）
C3: 4月 | D3: 5月 | E3: 6月 | F3: 7月 | G3: 8月 | H3: 9月 | I3: 10月 | J3: 11月 | K3: 12月 | L3: 1月 | M3: 2月 | N3: 3月
B4: リテラシーコース（後期100名）企業ゼミ | I4: 後期 企業ゼミ（100名）・AIリテラシー講座
B5: 実践コース（120名）／映像・VFX・3DCG・アニメ・ゲーム | I5: 分野別ゼミ＋AI深化
B6: 高度コース（40名）／VP・リアルタイムCGスペシャリスト | I6: VP専門コース（UE5・インカメラVFX）
B7: 全体（共通／成果発信） | C7: AI研修 | F7: AI研修 | G7: SIGGRAPH 2026 | I7: AI研修 | L7: AI研修 | N7: 成果報告
B8: 職 種 | C8: ２年目 令和9年度（2027年度）
C9: 4月 | D9: 5月 | E9: 6月 | F9: 7月 | G9: 8月 | H9: 9月 | I9: 10月 | J9: 11月 | K9: 12月 | L9: 1月 | M9: 2月 | N9: 3月
B10: 企業ゼミ：リテラシー（前期/100名+後期100名） | C10: 前期 企業ゼミ（100名）・AIリテラシー講座 | I10: 後期 企業ゼミ（100名）・AIリテラシー講座
B11: 企業ゼミ：実践（120名）／映像・VFX・3DCG・アニメ・ゲーム | C11: 企業ゼミ前期（拡大・AI深化） | I11: 後期 企業ゼミ＋ベーシックAI（継続）
B12: 高度コース（40名）／VP・リアルタイムCGスペシャリスト | E12: VP上級（作品制作・外部評価） | I12: VP専門コース（UE5・インカメラVFX）
B13: 全体（共通／成果発信） | C13: AI研修 | F13: AI研修 | G13: SIGGRAPH 2027 | I13: AI研修 | L13: AI研修 | N13: 成果報告
B14: 職 種 | C14: ３年目 令和10年度（2028年度）
C15: 4月 | D15: 5月 | E15: 6月 | F15: 7月 | G15: 8月 | H15: 9月 | I15: 10月 | J15: 11月 | K15: 12月 | L15: 1月 | M15: 2月 | N15: 3月
B16: 企業ゼミ：リテラシー（前期/100名+後期100名） | C16: 前期 企業ゼミ（100名）・AIリテラシー講座 | I16: 後期 企業ゼミ（100名）・AIリテラシー講座
B17: 企業ゼミ：実践（120名）／映像・VFX・3DCG・アニメ・ゲーム | C17: 企業ゼミ前期（拡大・AI深化） | I17: 後期 企業ゼミ＋ベーシックAI（継続）
B18: 高度コース（40名）／VP・リアルタイムCGスペシャリスト | E18: VP上級（作品制作・外部評価） | I18: VP専門コース（UE5・インカメラVFX）
B19: 全体（共通／成果発信） | C19: AI研修 | F19: AI研修 | G19: SIGGRAPH 2028 | I19: AI研修 | L19: AI研修 | N19: 成果報告

Sheet ７．連携先、８．指導者等
B1: ７．連携先 ※「プロジェクトに盛り込むべき観点④」に対応
B3: 【連携先一覧】
B4: 団体名 | C4: 状況 | D4: 種別 | E4: 専門分野 | F4: 所在地 | G4: 役割 | H4: 本プロジェクトに関連した実績
B5: ベネッセAI教育研究所 | C5: 内諾済 | D5: 産 | E5: 教育効果測定／EBPM評価／高大接続／オンライン教育普及 | F5: 東京都 | G5: ①大学との共催による企業ゼミ（リテラシー〜実践）の設計・運営、教育プログラムの設計。②受講生事前事後アセスメント、修了生3年継続追跡、EBPM評価、研究レポート共同編集。③全国教育機関への教育モデル展開支援 | H5: 長年にわたり全国の教育機関と接点を有し、教育効果測定・追跡調査・教材開発・オンライン教育普及で実績
B6: GROUNDRIDDIM（グラウンドリディム） | C6: 内諾済 | D6: 産 | E6: 映像制作／Music Video／バーチャルプロダクション映像 | F6: 埼玉県 | G6: MV・VP映像制作OJT受け入れ／実制作指導／業界マッチング／VP映像ワークフロー共同開発 | H6: 藤井風「きらり」MV（ストリーミング5億回超）等多数のMV・ライブ映像制作実績。代表・髙野良和は本学准教授として在籍。
B7: アニメ制作会社（複数社） | C7: 検討中 | D7: 産 | E7: アニメ制作 | F7: 都内ほか | G7: OJT受け入れ／実制作指導／インターンシップ／業界マッチング | H7: ※プロジェクト開始後に正式締結予定
B8: ゲーム制作会社／リアルタイム制作企業（複数社） | C8: 検討中 | D8: 産 | E8: ゲーム／リアルタイム制作 | F8: 都内ほか | G8: OJT受け入れ／実制作指導／インターンシップ | H8: ※プロジェクト開始後に正式締結予定
B9: AI制作支援企業／生成AIプラットフォーム企業 | C9: 検討中 | D9: 産 | E9: AI制作支援／生成AIプラットフォーム | F9: 国内外 | G9: AI Nativeワークフロー設計支援／教材提供／講師派遣 | H9: ※プロジェクト開始後に正式締結予定
B10: XR・ライブ演出企業 | C10: 検討中 | D10: 産 | E10: XR／ライブ演出 | F10: 都内ほか | G10: OJT受け入れ／実制作指導／業界マッチング | H10: ※プロジェクト開始後に正式締結予定
B11: Otis College of Art and Design | C11: 検討中 | D11: 産 | E11: アート・デザイン教育（米国） | F11: 米国ロサンゼルス | G11: 海外連携プログラム／海外スタジオ短期研修／教員交流 | H11: エカート教授が同校教授を兼任
B13: ８．指導者等 ※「プロジェクトに盛り込むべき観点④」に対応
B15: 【本プロジェクトの中核となる者】
B16: 氏名 | C16: 状況 | E16: 専門分野 | F16: 所属・職名 | G16: 役割 | H16: 本プロジェクトに関連した実績
B17: クリストファー・ハンス・エカート（Christopher Hans Eckardt） | C17: 本学教員 | E17: 国際的VFX／3DCG制作／VFX教育 | F17: デジタルハリウッド大学 教授（招聘予定）／Otis College of Art and Design 教授 | G17: 本事業の教育・研究の中核指導者。Framestore流ワークフローの継承指導、上級コース統括、海外連携の中核 | H17: Framestore Los Angeles 設立メンバー／MTV Video Music Award 最優秀視覚効果賞受賞（OutKast「Hey Ya!」）／北京冬季五輪ハンドオーバー演出／30年以上の国際的VFX実績
B19: 【指導者等一覧】
B20: 氏名 | C20: 状況 | E20: 専門分野 | F20: 所属・職名 | G20: 役割 | H20: 本プロジェクトに関連した実績
B21: 髙野良和 | C21: 本学教員 | E21: 映像制作・Music Video・VJ・広告映像 | F21: デジタルハリウッド大学 准教授 / GROUNDRIDDIM プロデューサー | G21: 映像制作演習・ゼミ指導・VP映像ワークフロー教育 | H21: 藤井風「きらり」MV（ストリーミング5億回超、2024年3月時点）プロデューサー。Yellow Magic Orchestra FUJI ROCK FESTIVAL'11 ライブVJ担当。セガ「ROOMANIA#203」・ナムコ「鉄拳４」CG開発参加。
B22: ヤーッコ・サーリ | C22: 本学教員 | E22: バーチャルプロダクション・Unreal Engine・リアルタイムCG・VFX | F22: デジタルハリウッド大学 特任准教授 / SonaGraf Co., Ltd. CEO | G22: VP・UE専門授業担当・リアルタイムCG指導 | H22: ASIAGRAPH 2021 Division I: CG Art Gallery 受賞。IMAGICA DIGITALSCAPE Unreal Engine アドバイザー歴任。Territory Studio等での国際VFX実績。フィンランド出身、2007年来日。
B23: 古岩 祥幸 | C23: 本学教員 | E23: 3DCG・キャラクターアニメーション・フルCG映像制作 | F23: デジタルハリウッド大学 非常勤講師 | G23: 3DCG演習・フルCG系ゼミ担当・キャラクターアニメーション指導 | H23: 株式会社ポリゴン・ピクチュアズにてレイアウト・キャラクターアニメーション担当（国内外CGアニメ多数）。2014年よりデジタルハリウッド大学講師、フルCG系ゼミ担当。
B24: ※ 欄が不足する場合は、適宜行を挿入してください。

Sheet ９．成果目標
B1: ９．成果目標
B3: 【アウトプット】
B4: コンテンツの制作・発信を支える中核的専門人材育成のためのプログラム実施件数 | D4: 目標値 | E4: 30件以上（3年累計）
D5: 目標値の 設定根拠 | E5: リテラシー・実践・高度の3階層×3年×複数開講＋FD研修（年2回×3年）＋出前授業（年4回×3年）＋サマースクール（年1回×3年）＋研究会等を含む。3年間で30件以上のプログラム実施を計画。
D6: 計測・算出 方法 | E6: 事務局における実施記録（開講記録、出前授業記録、研修記録、参加者名簿等）に基づき、年度ごとに集計。中間研究レポート・最終研究レポートにて公開。
B8: 連携先の教育機関、企業・団体、自治体、拠点形成数 | D8: 目標値 | E8: 177団体以上（3年累計：自治体15／中高75／高等教育機関45／各種学校42）＋業界団体・関係省庁等
D9: 目標値の 設定根拠 | E9: 全国の自治体15・中高75・高等教育機関45・各種学校42の累計177団体への教育モデル展開（教職員研修＋プログラム提供数延べ）に加え、業界横断連携企業群（5分野）と業界団体（CESA・VFX-JAPAN等）、関係省庁（経済産業省・文化庁・内閣府）への報告を計画。本学既存ネットワークおよびベネッセAI教育研究所の全国教育機関ネットワークを活用して達成。
D10: 計測・算出 方法 | E10: カリキュラム公開ライセンス契約数、FD研修受講機関数、出前授業実施校数、研究会共催・後援等の記録を事務局で管理し、ベネッセAI教育研究所と連携して年度ごとに集計。
B12: 【短期アウトカム】
B13: コンテンツの制作・発信を支える中核的専門人材の育成数 | D13: 目標値 | E13: 1,080名（3年累計）
D14: 目標値の 設定根拠 | E14: 【3階層構成】リテラシー600名（年200名×3年）＋実践360名（年120名×3年）＋高度120名（年40名×3年）＝累計1,080名。【算出根拠】リテラシー（年200名）は本学既存のAIリテラシー講座の受講者数、実践（年120名）は既存の該当ゼミ（3年生以降）の在籍人数、高度（年40名）は本学における今年度の履修見込み数を、それぞれ基準として算出した。いずれも本学（大学院2004・大学2005年開学）の現有教育リソースから積み上げ可能な水準。
D15: 計測・算出 方法 | E15: 受講生名簿、修了認定（カリキュラム修了要件達成）、ポートフォリオ評価により集計。ベネッセAI教育研究所による事前事後アセスメントで習得状況を定量検証。
B17: その他① 長期アウトカム | D17: 成果指標 | E17: 業界就業率（中級・上級修了生）／修了後3年継続従事率
D18: 目標値 | E18: 業界就業率70%以上／修了後3年継続従事率70%以上
D19: 目標値の 設定根拠 | E19: デジタルハリウッドグループ累計9万人以上の輩出実績、本学（大学・大学院）におけるPBL・企業連携教育を通じた即戦力人材輩出の実績に基づき設定。業界横断連携（5分野）による就業先の多様性が定着率向上に寄与。
D20: 計測・算出 方法 | E20: EBPM評価では、受講生の事前事後アセスメントによるスキル習得度、修了生3年継続追跡による業界就業率・継続従事率、産業横断的な就業先分布をエビデンスとして測定する。ベネッセAI教育研究所が要因分析を行い、業界標準コンピテンシーモデルの策定と経産省・文化庁への報告書を通じて政策立案・産業界に還元する。
B22: その他② 波及効果 | D22: 成果指標 | E22: 教材公開数／FD研修受講教員数／業界標準コンピテンシーモデル等の公開
D23: 目標値 | E23: 公開教材50本以上／FD研修受講教員150名以上／業界標準コンピテンシーモデル1件公開／国産デジタルデザインPF要件定義書1件公開／関連研究会3回以上開催／AIネイティブワークフロー公開事例30事例以上
D24: 目標値の 設定根拠 | E24: 本学のLEDウォール環境およびAIネイティブ教育環境を背景に、産業横断型3DCG制作中核人材育成モデルを公共財として展開する観点から設定。
D25: 計測・算出 方法 | E25: オンライン教育プラットフォーム上の教材公開数、FD研修参加者名簿、業界団体・関係省庁との共有記録、研究会実施記録に基づき年度ごとに集計。研究レポートで公開。

Sheet １０．収支予算書
A1: １０．収支予算書
A3: １．予算総括表
A5: ※別シートの「経費予定額（令和8年度・1年目）」「経費予定額（令和9年度・2年目）」「経費予定額（令和10年度・3年目）」の
A6: 金額の合計が転記されます。
A7: ※計算式が設定されていますので青色の欄には入力しないでください。
A8: ※応募団体の「消費税等仕入控除税額の取扱」について、必ず該当するものを選択してください。
A9: ※助成金交付要望額は必ず記入してください。
E10: 税区分番号
B11: 消費税等仕入控除税額の取扱 | C11: 【要選択：消費税等仕入控除税額の取扱】 | E11: =LEFT(C11,1) -> 【
A13: 費目 | B13: 種別 | C13: 金額 （単位：千円）
A14: 人件費 | B14: 賃金 | C14: ='経費予定額(令和8年度・1年目) '!L18+'経費予定額(令和9年度・2年目)'!L18+'経費予定額(令和10年度・3年目)'!L18 -> 52997
A15: 事業費 | B15: 諸謝金 | C15: ='経費予定額(令和8年度・1年目) '!L26+'経費予定額(令和9年度・2年目)'!L26+'経費予定額(令和10年度・3年目)'!L26 -> 10260
B16: 旅費 | C16: ='経費予定額(令和8年度・1年目) '!L31+'経費予定額(令和9年度・2年目)'!L31+'経費予定額(令和10年度・3年目)'!L31 -> 6000
B17: 借損料 | C17: ='経費予定額(令和8年度・1年目) '!L36+'経費予定額(令和9年度・2年目)'!L36+'経費予定額(令和10年度・3年目)'!L36 -> 104040
B18: 消耗品費 | C18: ='経費予定額(令和8年度・1年目) '!L41+'経費予定額(令和9年度・2年目)'!L41+'経費予定額(令和10年度・3年目)'!L41 -> 1350
B19: 会議費 | C19: ='経費予定額(令和8年度・1年目) '!L46+'経費予定額(令和9年度・2年目)'!L46+'経費予定額(令和10年度・3年目)'!L46 -> 3390
B20: 通信 運搬費 | C20: ='経費予定額(令和8年度・1年目) '!L51+'経費予定額(令和9年度・2年目)'!L51+'経費予定額(令和10年度・3年目)'!L51 -> 2520
B21: 雑役務費 | C21: ='経費予定額(令和8年度・1年目) '!L57+'経費予定額(令和9年度・2年目)'!L57+'経費予定額(令和10年度・3年目)'!L57 -> 7410
B22: 保険料 | C22: ='経費予定額(令和8年度・1年目) '!L62+'経費予定額(令和9年度・2年目)'!L62+'経費予定額(令和10年度・3年目)'!L62 -> 180 | E22: 事業費合計： | F22: =SUM(C15:C22) -> 135150
A23: 委 託 費 | C23: ='経費予定額(令和8年度・1年目) '!L63+'経費予定額(令和9年度・2年目)'!L63+'経費予定額(令和10年度・3年目)'!L63 -> 15000
A24: 助成対象経費 小計（ａ） | C24: =SUM(C14:C23) -> 203147
A25: 助成対象経費に含まれる消費税等の額（ｂ） | C25: ='経費予定額(令和8年度・1年目) '!L68+'経費予定額(令和9年度・2年目)'!L68+'経費予定額(令和10年度・3年目)'!L68 -> 11829
A26: 助成対象経費 合計（ａ－ｂ） | C26: =IF(OR($E$11="2",$E$11="3"),$C$24,$C$24-$C$25) -> 191318
A27: 収入見込額（ｃ） | C27: ='経費予定額(令和8年度・1年目) '!L75+'経費予定額(令和9年度・2年目)'!L75+'経費予定額(令和10年度・3年目)'!L75 -> 0
A28: 収支差（自己負担額） （ａ－ｃ） | C28: =C24-C27 -> 203147
B30: 助成金交付要望額（千円） | C30: =MIN(200000, C31) -> 191318 | D30: 下記上限額を参考に、助成金交付要望額を必ず記入してください。
B31: 参考：算定できる助成金の上限額（千円） | C31: =MIN(C26,C28) -> 191318 | D31: 助成対象経費の合計額もしくは自己負担金のどちらか小さいほうが自動で入力されます。

Sheet 経費予定額(令和8年度・1年目) 
A1: ◎各年度収支予定額
A2: ２．経費予定額（令和８年度・１年目）
A4: ※ | B4: ３年間の助成対象経費のうち、令和８年度（１年目）に掛かる経費の予定額を記入してください。
A5: ※ | B5: 必ず会計担当者が記載内容を確認するようにしてください。
A6: ※ | C6: 計算式が設定されていますので青色の欄には入力しないでください。
A7: ※ | B7: 金額欄には消費税等込みの金額を記入してください。
A8: ※ | B8: 軽減税率の対象となる経費は、「軽減税率」欄に○を記入してください。
A9: ※ | B9: 課税対象外(人件費・海外で支払う経費等（団体により異なるため会計担当者に確認すること）)の経費は、「課税対象外」欄に○を記入してください。
A10: ※ | B10: 欄が不足する場合は行を挿入してください。複数ページにわたっても結構です。
A11: ※ | B11: 提出前に必ず検算するようにしてください。
N12: 単位：円
A13: 費目 | B13: 種別 | D13: 内訳（支払い内容） | E13: 数量・単位 | G13: 数量・単位 | I13: 数量・単位 | K13: 単価 （税込・円） | L13: 金額 （千円） | M13: 軽減 税率 | N13: 課税 対象外
A14: 人件費 | B14: 賃金 | D14: プログラム・ディレクター（事業統括） | E14: 1 | F14: 名 | G14: 6 | H14: 月 | I14: 1 | J14: 年 | K14: 750000 | L14: =IF(ISNUMBER(K14),(ROUNDDOWN(PRODUCT(E14,G14,I14,K14)/1000,0)),"") -> 4500 | N14: ○
D15: 研究員・教育担当（カリキュラム開発・運営） | E15: 2 | F15: 名 | G15: 6 | H15: 月 | I15: 1 | J15: 年 | K15: 500000 | L15: =IF(ISNUMBER(K15),(ROUNDDOWN(PRODUCT(E15,G15,I15,K15)/1000,0)),"") -> 6000 | N15: ○
D16: 事務担当・経理担当（事務局運営） | E16: 2 | F16: 名 | G16: 6 | H16: 月 | I16: 1 | J16: 年 | K16: 208333 | L16: =IF(ISNUMBER(K16),(ROUNDDOWN(PRODUCT(E16,G16,I16,K16)/1000,0)),"") -> 2499 | N16: ○
L17: =IF(ISNUMBER(K17),(ROUNDDOWN(PRODUCT(E17,G17,I17,K17)/1000,0)),"")
D18: 小計 | L18: =SUM(L14:L17) -> 12999 | P18: 課税外 | Q18: =SUMIF(N14:N17,"○",L14:L17) -> 12999 | S18: 軽減 | T18: =SUMIF(M14:M17,"○",L14:L17) -> 0 | V18: 標準 | W18: =$L$18-$Q$18-$T$18 -> 0
A19: 事業費 | B19: 諸謝金 | D19: エカート教授特別講義謝金 | E19: 5 | F19: 回 | G19: 1 | H19: 名 | I19: 1 | J19: 日 | K19: 100000 | L19: =IF(ISNUMBER(K19),(ROUNDDOWN(PRODUCT(E19,G19,I19,K19)/1000,0)),"") -> 500 | N19: ○
D20: 海外講師招聘謝金 | E20: 2 | F20: 名 | G20: 1 | H20: 回 | I20: 1 | J20: 日 | K20: 300000 | L20: =IF(ISNUMBER(K20),(ROUNDDOWN(PRODUCT(E20,G20,I20,K20)/1000,0)),"") -> 600 | N20: ○
D21: 出前授業・FD研修講師謝金 | E21: 6 | F21: 回 | G21: 1 | H21: 名 | I21: 1 | J21: 日 | K21: 95000 | L21: =IF(ISNUMBER(K21),(ROUNDDOWN(PRODUCT(E21,G21,I21,K21)/1000,0)),"") -> 570 | N21: ○
D22: 髙野良和 VP映像演習・特別指導謝金 | E22: 20 | F22: 回 | G22: 1 | H22: 名 | I22: 1 | J22: 年 | K22: 25000 | L22: =IF(ISNUMBER(K22),(ROUNDDOWN(PRODUCT(E22,G22,I22,K22)/1000,0)),"") -> 500
D23: ヤーッコ・サーリ VP/UE専門指導謝金 | E23: 20 | F23: 回 | G23: 1 | H23: 名 | I23: 1 | J23: 年 | K23: 25000 | L23: =IF(ISNUMBER(K23),(ROUNDDOWN(PRODUCT(E23,G23,I23,K23)/1000,0)),"") -> 500
D24: 古岩祥幸 3DCG・キャラクターアニメーション指導謝金 | E24: 20 | F24: 回 | G24: 1 | H24: 名 | I24: 1 | J24: 年 | K24: 25000 | L24: =IF(ISNUMBER(K24),(ROUNDDOWN(PRODUCT(E24,G24,I24,K24)/1000,0)),"") -> 500
D25: クリス・エカート 契約外指導補助謝金 | E25: 5 | F25: 回 | G25: 1 | H25: 名 | I25: 1 | J25: 年 | K25: 50000 | L25: =IF(ISNUMBER(K25),(ROUNDDOWN(PRODUCT(E25,G25,I25,K25)/1000,0)),"") -> 250
D26: 小計 | L26: =SUM(L19:L25) -> 3420 | P26: 課税外 | Q26: =SUMIF(N19:N25,"○",L19:L25) -> 1670 | S26: 軽減 | T26: =SUMIF(M19:M25,"○",L19:L25) -> 0 | V26: 標準 | W26: =$L$26-$Q$26-$T$26 -> 1750
B27: 旅費 | D27: 海外連携先出張旅費（Otis College等） | E27: 4 | F27: 回 | G27: 1 | H27: 名 | I27: 1 | J27: 式 | K27: 200000 | L27: =IF(ISNUMBER(K27),(ROUNDDOWN(PRODUCT(E27,G27,I27,K27)/1000,0)),"") -> 800
L28: =IF(ISNUMBER(K28),(ROUNDDOWN(PRODUCT(E28,G28,I28,K28)/1000,0)),"")
D29: SIGGRAPH 2026参加（ヤーッコ・サーリ）航空券（EC）・宿泊4泊・参加費 | E29: 1 | F29: 名 | G29: 1 | H29: 式 | I29: 1 | J29: 式 | K29: 600000 | L29: =IF(ISNUMBER(K29),(ROUNDDOWN(PRODUCT(E29,G29,I29,K29)/1000,0)),"") -> 600
D30: SIGGRAPH 2026参加（クリス・エカート）航空券（EC）・宿泊4泊・参加費 | E30: 1 | F30: 名 | G30: 1 | H30: 式 | I30: 1 | J30: 式 | K30: 600000 | L30: =IF(ISNUMBER(K30),(ROUNDDOWN(PRODUCT(E30,G30,I30,K30)/1000,0)),"") -> 600
D31: 小計 | L31: =SUM(L27:L30) -> 2000 | P31: 課税外 | Q31: =SUMIF(N27:N30,"○",L27:L30) -> 0 | S31: 軽減 | T31: =SUMIF(M27:M30,"○",L27:L30) -> 0 | V31: 標準 | W31: =$L$31-$Q$31-$T$31 -> 2000
B32: 借損料 | D32: AIツール利用料：リテラシー | E32: 200 | F32: 名 | G32: 6 | H32: 月 | I32: 1 | J32: 年 | K32: 17000 | L32: =IF(ISNUMBER(K32),(ROUNDDOWN(PRODUCT(E32,G32,I32,K32)/1000,0)),"") -> 20400
D33: AIツール利用料：実践 | E33: 120 | F33: 名 | G33: 6 | H33: 月 | I33: 1 | J33: 年 | K33: 17000 | L33: =IF(ISNUMBER(K33),(ROUNDDOWN(PRODUCT(E33,G33,I33,K33)/1000,0)),"") -> 12240
D34: AIツール利用料：高度 | E34: 20 | F34: 名 | G34: 6 | H34: 月 | I34: 1 | J34: 年 | K34: 17000 | L34: =IF(ISNUMBER(K34),(ROUNDDOWN(PRODUCT(E34,G34,I34,K34)/1000,0)),"") -> 2040
L35: =IF(ISNUMBER(K35),(ROUNDDOWN(PRODUCT(E35,G35,I35,K35)/1000,0)),"")
D36: 小計 | L36: =SUM(L32:L35) -> 34680 | P36: 課税外 | Q36: =SUMIF(N32:N35,"○",L32:L35) -> 0 | S36: 軽減 | T36: =SUMIF(M32:M35,"○",L32:L35) -> 0 | V36: 標準 | W36: =$L$36-$Q$36-$T$36 -> 34680
B37: 消耗品費 | D37: OJT用ポータブルSSD（上級・中級受講生用データ持出し） | E37: 30 | F37: 本 | G37: 1 | H37: 式 | I37: 1 | J37: 年 | K37: 10000 | L37: =IF(ISNUMBER(K37),(ROUNDDOWN(PRODUCT(E37,G37,I37,K37)/1000,0)),"") -> 300
D38: 研修用テキスト・教材印刷費 | E38: 1 | F38: 式 | G38: 1 | H38: 式 | I38: 1 | J38: 年 | K38: 150000 | L38: =IF(ISNUMBER(K38),(ROUNDDOWN(PRODUCT(E38,G38,I38,K38)/1000,0)),"") -> 150
L39: =IF(ISNUMBER(K39),(ROUNDDOWN(PRODUCT(E39,G39,I39,K39)/1000,0)),"")
L40: =IF(ISNUMBER(K40),(ROUNDDOWN(PRODUCT(E40,G40,I40,K40)/1000,0)),"")
D41: 小計 | L41: =SUM(L37:L40) -> 450 | P41: 課税外 | Q41: =SUMIF(N37:N40,"○",L37:L40) -> 0 | S41: 軽減 | T41: =SUMIF(M37:M40,"○",L37:L40) -> 0 | V41: 標準 | W41: =$L$41-$Q$41-$T$41 -> 450
...

Sheet 経費予定額(令和9年度・2年目)
A2: ３．経費予定額（令和９年度・２年目）
A4: ※ | B4: ３年間の助成対象経費のうち、令和９年度（２年目）に掛かる経費の予定額を記入してください。
A5: ※ | B5: 必ず会計担当者が記載内容を確認するようにしてください。
A6: ※ | C6: 計算式が設定されていますので青色の欄には入力しないでください。
A7: ※ | B7: 金額欄には消費税等込みの金額を記入してください。
A8: ※ | B8: 軽減税率の対象となる経費は、「軽減税率」欄に○を記入してください。
A9: ※ | B9: 課税対象外(人件費・海外で支払う経費等（団体により異なるため会計担当者に確認すること）)の経費は、「課税対象外」欄に○を記入してください。
A10: ※ | B10: 欄が不足する場合は行を挿入してください。複数ページにわたっても結構です。
A11: ※ | B11: 提出前に必ず検算するようにしてください。
N12: 単位：円
A13: 費目 | B13: 種別 | D13: 内訳（支払い内容） | E13: 数量・単位 | G13: 数量・単位 | I13: 数量・単位 | K13: 単価 （税込・円） | L13: 金額 （千円） | M13: 軽減 税率 | N13: 課税 対象外
A14: 人件費 | B14: 賃金 | D14: プログラム・ディレクター（事業統括） | E14: 1 | F14: 名 | G14: 12 | H14: 月 | I14: 1 | J14: 年 | K14: 750000 | L14: =IF(ISNUMBER(K14),(ROUNDDOWN(PRODUCT(E14,G14,I14,K14)/1000,0)),"") -> 9000 | N14: ○
D15: 研究員・教育担当（カリキュラム開発・運営） | E15: 1 | F15: 名 | G15: 12 | H15: 月 | I15: 1 | J15: 年 | K15: 500000 | L15: =IF(ISNUMBER(K15),(ROUNDDOWN(PRODUCT(E15,G15,I15,K15)/1000,0)),"") -> 6000 | N15: ○
D16: 事務担当・経理担当（事務局運営） | E16: 2 | F16: 名 | G16: 12 | H16: 月 | I16: 1 | J16: 年 | K16: 208333 | L16: =IF(ISNUMBER(K16),(ROUNDDOWN(PRODUCT(E16,G16,I16,K16)/1000,0)),"") -> 4999 | N16: ○
L17: =IF(ISNUMBER(K17),(ROUNDDOWN(PRODUCT(E17,G17,I17,K17)/1000,0)),"")
D18: 小計 | L18: =SUM(L14:L17) -> 19999 | P18: 課税外 | Q18: =SUMIF(N14:N17,"○",L14:L17) -> 19999 | S18: 軽減 | T18: =SUMIF(M14:M17,"○",L14:L17) -> 0 | V18: 標準 | W18: =$L$18-$Q$18-$T$18 -> 0
A19: 事業費 | B19: 諸謝金 | D19: エカート教授特別講義謝金 | E19: 5 | F19: 回 | G19: 1 | H19: 名 | I19: 1 | J19: 日 | K19: 100000 | L19: =IF(ISNUMBER(K19),(ROUNDDOWN(PRODUCT(E19,G19,I19,K19)/1000,0)),"") -> 500 | N19: ○
D20: 海外講師招聘謝金 | E20: 2 | F20: 名 | G20: 1 | H20: 回 | I20: 1 | J20: 日 | K20: 300000 | L20: =IF(ISNUMBER(K20),(ROUNDDOWN(PRODUCT(E20,G20,I20,K20)/1000,0)),"") -> 600 | N20: ○
D21: 出前授業・FD研修講師謝金 | E21: 6 | F21: 回 | G21: 1 | H21: 名 | I21: 1 | J21: 日 | K21: 95000 | L21: =IF(ISNUMBER(K21),(ROUNDDOWN(PRODUCT(E21,G21,I21,K21)/1000,0)),"") -> 570 | N21: ○
D22: 髙野良和 VP映像演習・特別指導謝金 | E22: 20 | F22: 回 | G22: 1 | H22: 式 | I22: 1 | J22: 式 | K22: 25000 | L22: =IF(ISNUMBER(K22),(ROUNDDOWN(PRODUCT(E22,G22,I22,K22)/1000,0)),"") -> 500
D23: ヤーッコ・サーリ VP/UE専門指導謝金 | E23: 20 | F23: 回 | G23: 1 | H23: 式 | I23: 1 | J23: 式 | K23: 25000 | L23: =IF(ISNUMBER(K23),(ROUNDDOWN(PRODUCT(E23,G23,I23,K23)/1000,0)),"") -> 500
D24: 古岩祥幸 3DCG・アニメーション指導謝金 | E24: 20 | F24: 回 | G24: 1 | H24: 式 | I24: 1 | J24: 式 | K24: 25000 | L24: =IF(ISNUMBER(K24),(ROUNDDOWN(PRODUCT(E24,G24,I24,K24)/1000,0)),"") -> 500
D25: クリス・エカート 契約外指導補助謝金 | E25: 5 | F25: 回 | G25: 1 | H25: 式 | I25: 1 | J25: 式 | K25: 50000 | L25: =IF(ISNUMBER(K25),(ROUNDDOWN(PRODUCT(E25,G25,I25,K25)/1000,0)),"") -> 250
D26: 小計 | L26: =SUM(L19:L25) -> 3420 | P26: 課税外 | Q26: =SUMIF(N19:N22,"○",L19:L22) -> 1670 | S26: 軽減 | T26: =SUMIF(M19:M22,"○",L19:L22) -> 0 | V26: 標準 | W26: =$L$26-$Q$26-$T$26 -> 1750
B27: 旅費 | D27: 海外連携先出張旅費（Otis College等） | E27: 4 | F27: 回 | G27: 1 | H27: 名 | I27: 1 | J27: 式 | K27: 200000 | L27: =IF(ISNUMBER(K27),(ROUNDDOWN(PRODUCT(E27,G27,I27,K27)/1000,0)),"") -> 800
L28: =IF(ISNUMBER(K28),(ROUNDDOWN(PRODUCT(E28,G28,I28,K28)/1000,0)),"")
D29: SIGGRAPH 2027参加（ヤーッコ・サーリ）航空券（EC）・宿泊4泊・参加費 | E29: 1 | F29: 名 | G29: 1 | H29: 式 | I29: 1 | J29: 式 | K29: 600000 | L29: =IF(ISNUMBER(K29),(ROUNDDOWN(PRODUCT(E29,G29,I29,K29)/1000,0)),"") -> 600
D30: SIGGRAPH 2027参加（クリス・エカート）航空券（EC）・宿泊4泊・参加費 | E30: 1 | F30: 名 | G30: 1 | H30: 式 | I30: 1 | J30: 式 | K30: 600000 | L30: =IF(ISNUMBER(K30),(ROUNDDOWN(PRODUCT(E30,G30,I30,K30)/1000,0)),"") -> 600
D31: 小計 | L31: =SUM(L27:L30) -> 2000 | P31: 課税外 | Q31: =SUMIF(N27:N30,"○",L27:L30) -> 0 | S31: 軽減 | T31: =SUMIF(M27:M30,"○",L27:L30) -> 0 | V31: 標準 | W31: =$L$31-$Q$31-$T$31 -> 2000
B32: 借損料 | D32: AIツール利用料：リテラシー | E32: 200 | F32: 名 | G32: 12 | H32: 月 | I32: 1 | J32: 年 | K32: 8500 | L32: =IF(ISNUMBER(K32),(ROUNDDOWN(PRODUCT(E32,G32,I32,K32)/1000,0)),"") -> 20400
D33: AIツール利用料：実践 | E33: 120 | F33: 名 | G33: 12 | H33: 月 | I33: 1 | J33: 年 | K33: 8500 | L33: =IF(ISNUMBER(K33),(ROUNDDOWN(PRODUCT(E33,G33,I33,K33)/1000,0)),"") -> 12240
D34: AIツール利用料：高度 | E34: 20 | F34: 名 | G34: 12 | H34: 月 | I34: 1 | J34: 年 | K34: 8500 | L34: =IF(ISNUMBER(K34),(ROUNDDOWN(PRODUCT(E34,G34,I34,K34)/1000,0)),"") -> 2040
F35: 式 | H35: 月 | J35: 年 | L35: =IF(ISNUMBER(K35),(ROUNDDOWN(PRODUCT(E35,G35,I35,K35)/1000,0)),"")
D36: 小計 | L36: =SUM(L32:L35) -> 34680 | P36: 課税外 | Q36: =SUMIF(N32:N35,"○",L32:L35) -> 0 | S36: 軽減 | T36: =SUMIF(M32:M35,"○",L32:L35) -> 0 | V36: 標準 | W36: =$L$36-$Q$36-$T$36 -> 34680
B37: 消耗品費 | D37: OJT用ポータブルSSD（上級・中級受講生用データ持出し） | E37: 30 | F37: 本 | G37: 1 | H37: 式 | I37: 1 | J37: 年 | K37: 10000 | L37: =IF(ISNUMBER(K37),(ROUNDDOWN(PRODUCT(E37,G37,I37,K37)/1000,0)),"") -> 300
D38: 研修用テキスト・教材印刷費 | E38: 1 | F38: 式 | G38: 1 | H38: 式 | I38: 1 | J38: 年 | K38: 150000 | L38: =IF(ISNUMBER(K38),(ROUNDDOWN(PRODUCT(E38,G38,I38,K38)/1000,0)),"") -> 150
L39: =IF(ISNUMBER(K39),(ROUNDDOWN(PRODUCT(E39,G39,I39,K39)/1000,0)),"")
L40: =IF(ISNUMBER(K40),(ROUNDDOWN(PRODUCT(E40,G40,I40,K40)/1000,0)),"")
D41: 小計 | L41: =SUM(L37:L40) -> 450 | P41: 課税外 | Q41: =SUMIF(N37:N40,"○",L37:L40) -> 0 | S41: 軽減 | T41: =SUMIF(M37:M40,"○",L37:L40) -> 0 | V41: 標準 | W41: =$L$41-$Q$41-$T$41 -> 450
B42: 会議費 | D42: 研究会会場費・運営費 | E42: 4 | F42: 回 | G42: 1 | H42: 日 | I42: 1 | J42: 式 | K42: 120000 | L42: =IF(ISNUMBER(K42),(ROUNDDOWN(PRODUCT(E42,G42,I42,K42)/1000,0)),"") -> 480
...

Sheet 経費予定額(令和10年度・3年目)
A2: ４．経費予定額（令和１０年度・３年目）
A4: ※ | B4: ３年間の助成対象経費のうち、令和１０年度（３年目）に掛かる経費の予定額を記入してください。
A5: ※ | B5: 必ず会計担当者が記載内容を確認するようにしてください。
A6: ※ | C6: 計算式が設定されていますので青色の欄には入力しないでください。
A7: ※ | B7: 金額欄には消費税等込みの金額を記入してください。
A8: ※ | B8: 軽減税率の対象となる経費は、「軽減税率」欄に○を記入してください。
A9: ※ | B9: 課税対象外(人件費・海外で支払う経費等（団体により異なるため会計担当者に確認すること）)の経費は、「課税対象外」欄に○を記入してください。
A10: ※ | B10: 欄が不足する場合は行を挿入してください。複数ページにわたっても結構です。
A11: ※ | B11: 提出前に必ず検算するようにしてください。
N12: 単位：円
A13: 費目 | B13: 種別 | D13: 内訳（支払い内容） | E13: 数量・単位 | G13: 数量・単位 | I13: 数量・単位 | K13: 単価 （税込・円） | L13: 金額 （千円） | M13: 軽減 税率 | N13: 課税 対象外
A14: 人件費 | B14: 賃金 | D14: プログラム・ディレクター（事業統括） | E14: 1 | F14: 名 | G14: 12 | H14: 月 | I14: 1 | J14: 年 | K14: 750000 | L14: =IF(ISNUMBER(K14),(ROUNDDOWN(PRODUCT(E14,G14,I14,K14)/1000,0)),"") -> 9000 | N14: ○
D15: 研究員・教育担当（カリキュラム開発・運営） | E15: 1 | F15: 名 | G15: 12 | H15: 月 | I15: 1 | J15: 年 | K15: 500000 | L15: =IF(ISNUMBER(K15),(ROUNDDOWN(PRODUCT(E15,G15,I15,K15)/1000,0)),"") -> 6000 | N15: ○
D16: 事務担当・経理担当（事務局運営） | E16: 2 | F16: 名 | G16: 12 | H16: 月 | I16: 1 | J16: 年 | K16: 208333 | L16: =IF(ISNUMBER(K16),(ROUNDDOWN(PRODUCT(E16,G16,I16,K16)/1000,0)),"") -> 4999 | N16: ○
L17: =IF(ISNUMBER(K17),(ROUNDDOWN(PRODUCT(E17,G17,I17,K17)/1000,0)),"")
D18: 小計 | L18: =SUM(L14:L17) -> 19999 | P18: 課税外 | Q18: =SUMIF(N14:N17,"○",L14:L17) -> 19999 | S18: 軽減 | T18: =SUMIF(M14:M17,"○",L14:L17) -> 0 | V18: 標準 | W18: =$L$18-$Q$18-$T$18 -> 0
A19: 事業費 | B19: 諸謝金 | D19: エカート教授特別講義謝金 | E19: 5 | F19: 回 | G19: 1 | H19: 名 | I19: 1 | J19: 日 | K19: 100000 | L19: =IF(ISNUMBER(K19),(ROUNDDOWN(PRODUCT(E19,G19,I19,K19)/1000,0)),"") -> 500 | N19: ○
D20: 海外講師招聘謝金 | E20: 2 | F20: 名 | G20: 1 | H20: 回 | I20: 1 | J20: 日 | K20: 300000 | L20: =IF(ISNUMBER(K20),(ROUNDDOWN(PRODUCT(E20,G20,I20,K20)/1000,0)),"") -> 600 | N20: ○
D21: 出前授業・FD研修講師謝金 | E21: 6 | F21: 回 | G21: 1 | H21: 名 | I21: 1 | J21: 日 | K21: 95000 | L21: =IF(ISNUMBER(K21),(ROUNDDOWN(PRODUCT(E21,G21,I21,K21)/1000,0)),"") -> 570 | N21: ○
D22: 髙野良和 VP映像演習・特別指導謝金 | E22: 20 | F22: 回 | G22: 1 | H22: 式 | I22: 1 | J22: 式 | K22: 25000 | L22: =IF(ISNUMBER(K22),(ROUNDDOWN(PRODUCT(E22,G22,I22,K22)/1000,0)),"") -> 500
D23: ヤーッコ・サーリ VP/UE専門指導謝金 | E23: 20 | F23: 回 | G23: 1 | H23: 式 | I23: 1 | J23: 式 | K23: 25000 | L23: =IF(ISNUMBER(K23),(ROUNDDOWN(PRODUCT(E23,G23,I23,K23)/1000,0)),"") -> 500
D24: 古岩祥幸 3DCG・アニメーション指導謝金 | E24: 20 | F24: 回 | G24: 1 | H24: 式 | I24: 1 | J24: 式 | K24: 25000 | L24: =IF(ISNUMBER(K24),(ROUNDDOWN(PRODUCT(E24,G24,I24,K24)/1000,0)),"") -> 500
D25: クリス・エカート 契約外指導補助謝金 | E25: 5 | F25: 回 | G25: 1 | H25: 式 | I25: 1 | J25: 式 | K25: 50000 | L25: =IF(ISNUMBER(K25),(ROUNDDOWN(PRODUCT(E25,G25,I25,K25)/1000,0)),"") -> 250
D26: 小計 | L26: =SUM(L19:L25) -> 3420 | P26: 課税外 | Q26: =SUMIF(N19:N22,"○",L19:L22) -> 1670 | S26: 軽減 | T26: =SUMIF(M19:M22,"○",L19:L22) -> 0 | V26: 標準 | W26: =$L$26-$Q$26-$T$26 -> 1750
B27: 旅費 | D27: 海外連携先出張旅費（Otis College等） | E27: 4 | F27: 回 | G27: 1 | H27: 名 | I27: 1 | J27: 式 | K27: 200000 | L27: =IF(ISNUMBER(K27),(ROUNDDOWN(PRODUCT(E27,G27,I27,K27)/1000,0)),"") -> 800
L28: =IF(ISNUMBER(K28),(ROUNDDOWN(PRODUCT(E28,G28,I28,K28)/1000,0)),"")
D29: SIGGRAPH 2028参加（ヤーッコ・サーリ）航空券（EC）・宿泊4泊・参加費 | E29: 1 | F29: 名 | G29: 1 | H29: 式 | I29: 1 | J29: 式 | K29: 600000 | L29: =IF(ISNUMBER(K29),(ROUNDDOWN(PRODUCT(E29,G29,I29,K29)/1000,0)),"") -> 600
D30: SIGGRAPH 2028参加（クリス・エカート）航空券（EC）・宿泊4泊・参加費 | E30: 1 | F30: 名 | G30: 1 | H30: 式 | I30: 1 | J30: 式 | K30: 600000 | L30: =IF(ISNUMBER(K30),(ROUNDDOWN(PRODUCT(E30,G30,I30,K30)/1000,0)),"") -> 600
D31: 小計 | L31: =SUM(L27:L30) -> 2000 | P31: 課税外 | Q31: =SUMIF(N27:N30,"○",L27:L30) -> 0 | S31: 軽減 | T31: =SUMIF(M27:M30,"○",L27:L30) -> 0 | V31: 標準 | W31: =$L$31-$Q$31-$T$31 -> 2000
B32: 借損料 | D32: AIツール利用料：リテラシー | E32: 200 | F32: 名 | G32: 12 | H32: 月 | I32: 1 | J32: 年 | K32: 8500 | L32: =IF(ISNUMBER(K32),(ROUNDDOWN(PRODUCT(E32,G32,I32,K32)/1000,0)),"") -> 20400
D33: AIツール利用料：実践 | E33: 120 | F33: 名 | G33: 12 | H33: 月 | I33: 1 | J33: 年 | K33: 8500 | L33: =IF(ISNUMBER(K33),(ROUNDDOWN(PRODUCT(E33,G33,I33,K33)/1000,0)),"") -> 12240
D34: AIツール利用料：高度 | E34: 20 | F34: 名 | G34: 12 | H34: 月 | I34: 1 | J34: 年 | K34: 8500 | L34: =IF(ISNUMBER(K34),(ROUNDDOWN(PRODUCT(E34,G34,I34,K34)/1000,0)),"") -> 2040
F35: 式 | H35: 月 | I35: 1 | J35: 年 | L35: =IF(ISNUMBER(K35),(ROUNDDOWN(PRODUCT(E35,G35,I35,K35)/1000,0)),"")
D36: 小計 | L36: =SUM(L32:L35) -> 34680 | P36: 課税外 | Q36: =SUMIF(N32:N35,"○",L32:L35) -> 0 | S36: 軽減 | T36: =SUMIF(M32:M35,"○",L32:L35) -> 0 | V36: 標準 | W36: =$L$36-$Q$36-$T$36 -> 34680
B37: 消耗品費 | D37: OJT用ポータブルSSD（上級・中級受講生用データ持出し） | E37: 30 | F37: 本 | G37: 1 | H37: 式 | I37: 1 | J37: 年 | K37: 10000 | L37: =IF(ISNUMBER(K37),(ROUNDDOWN(PRODUCT(E37,G37,I37,K37)/1000,0)),"") -> 300
D38: 研修用テキスト・教材印刷費 | E38: 1 | F38: 式 | G38: 1 | H38: 式 | I38: 1 | J38: 年 | K38: 150000 | L38: =IF(ISNUMBER(K38),(ROUNDDOWN(PRODUCT(E38,G38,I38,K38)/1000,0)),"") -> 150
L39: =IF(ISNUMBER(K39),(ROUNDDOWN(PRODUCT(E39,G39,I39,K39)/1000,0)),"")
L40: =IF(ISNUMBER(K40),(ROUNDDOWN(PRODUCT(E40,G40,I40,K40)/1000,0)),"")
D41: 小計 | L41: =SUM(L37:L40) -> 450 | P41: 課税外 | Q41: =SUMIF(N37:N40,"○",L37:L40) -> 0 | S41: 軽減 | T41: =SUMIF(M37:M40,"○",L37:L40) -> 0 | V41: 標準 | W41: =$L$41-$Q$41-$T$41 -> 450
B42: 会議費 | D42: 研究会会場費・運営費 | E42: 4 | F42: 回 | G42: 1 | H42: 日 | I42: 1 | J42: 式 | K42: 120000 | L42: =IF(ISNUMBER(K42),(ROUNDDOWN(PRODUCT(E42,G42,I42,K42)/1000,0)),"") -> 480
...

Sheet 誓約書
B3: 誓 約 書
C5: 当法人（団体）は、下記１及び２のいずれにも該当しません。また、将来においても該当することはありません。 この誓約が虚偽であり、又はこの誓約に反したことにより、当方が不利益を被ることとなっても、異議は一切申し立てません。 また、当方の個人情報を警察に提供することについて同意します。
B7: 記
D9: １ 助成金の交付を受ける団体として不適当な者 (1) 法人等（個人、法人又は団体をいう。）の役員等（個人である場合はその者、法人であ る場合は役員又は支店若しくは営業所（常時契約を締結する事務所をいう。）の代表者、 団体である場合は代表者、理事等、その他経営に実質的に関与している者をいう。）が、 暴力団（暴力団員による不当な行為の防止等に関する法律（平成３年法律第77号）第２ 条第２号に規定する暴力団をいう。以下同じ）又は暴力団員（同法第２条第６号に規定 する暴力団員をいう。以下同じ。）であるとき (2) 役員等が、自己、自社若しくは第三者の不正の利益を図る目的、又は第三者に損害を 加える目的をもって、暴力団又は暴力団員を利用するなどしているとき (3) 役員等が、暴力団又は暴力団員に対して、資金等を供給し、又は便宜を供与する など直接的あるいは積極的に暴力団の維持、運営に協力し、若しくは関与しているとき (4) 役員等が、暴力団又は暴力団員であることを知りながらこれを不当に利用するなど しているとき (5) 役員等が、暴力団又は暴力団員と社会的に非難されるべき関係を有しているとき
D10: ２ 助成金の交付を受ける団体として不適当な行為をする者 (1) 暴力的な要求行為を行う者 (2) 法的な責任を超えた不当な要求行為を行う者 (3) 取引に関して脅迫的な言動をし、又は暴力を用いる行為を行う者 (4) 偽計又は威力を用いて契約担当官等の業務を妨害する行為を行う者 (5) その他前各号に準ずる行為を行う者
D12: 令和 年 月 日
E13: 住所（又は所在地） | F13: 〒101-0062 東京都千代田区神田駿河台4-6
F14: 御茶ノ水ソラシティ アカデミア 4F
E15: 団体名 | F15: デジタルハリウッド株式会社
E16: 代表者役職名・氏名 | F16: 代表取締役社長兼CEO 藤井雅徳
D18: ※ 役員の氏名及び生年月日が明らかとなる資料を添付すること。

Sheet 芸文振確認用
A1: 表紙 ※テスト済 | B1: 応募日時 | C1: =表紙!N8 -> 令和８年 月 日
B2: 団体名 | C2: =表紙!K14 -> デジタルハリウッド株式会社
B3: 〒 | C3: =表紙!K16 -> 〒101-0062
B4: 住所（所在地） | C4: =表紙!K17 -> 東京都千代田区神田駿河台4-6 御茶ノ水ソラシティ アカデミア 4F
B5: 代表者の職名・氏名 | C5: =表紙!K19 -> 代表取締役社長兼CEO 藤井雅徳
B6: １．プロジェクト名 プロジェクト名は採択時の公表資料に 掲載されますのでご留意ください | C6: =表紙!H27 -> AI・バーチャルプロダクションを活用した3DCG制作人材育成事業 ─ AI時代の3DCG制作フロー高度化を担う中核人材の育成 ─
B7: ２．実 施 期 間 | C7: =表紙!H28 -> 交付内定日～令和１１年３月３１日
B8: ３．対 象 分 野 | C8: =表紙!H29 -> 映像
B9: 「その他」の場合、右欄に当該分野名を記載してください | C9: =表紙!H30 -> 0
B10: ４．要望額 （千円） | C10: =表紙!H31 -> 191318
B11: 事業責任者 所属・職名 | C11: =表紙!G34 -> デジタルハリウッド大学 学長
B12: 事業責任者 フリガナ | C12: =表紙!G35 -> フジイ ナオタカ
B13: 事業責任者 氏名 | C13: =表紙!G36 -> 藤井 直敬
B14: 事業責任者 電話 | C14: =表紙!M34 -> 【要記入：電話】
B15: 事業責任者 メールアドレス | C15: =表紙!M35 -> 【要記入：メール】
B16: 経理責任者 所属・職名 | C16: =表紙!G37 -> 【要記入：所属・職名】
B17: 経理責任者 フリガナ | C17: =表紙!G38 -> 【要記入：フリガナ】
B18: 経理責任者 氏名 | C18: =表紙!G39 -> 【要記入：氏名】
B19: 経理責任者 電話 | C19: =表紙!M37 -> 【要記入：電話】
B20: 経理責任者 メールアドレス | C20: =表紙!M38 -> 【要記入：メール】
B21: 事務担当者 所属・職名 | C21: =表紙!G40 -> 【要記入：所属・職名】
B22: 事務担当者 フリガナ | C22: =表紙!G41 -> 【要記入：フリガナ】
B23: 事務担当者 氏名 | C23: =表紙!G42 -> 【要記入：氏名】
B24: 事務担当者 電話 | C24: =表紙!M40 -> 【要記入：電話】
B25: 事務担当者 メールアドレス | C25: =表紙!M41 -> 【要記入：メール】
B26: 資料の 送付先 | C26: =表紙!F43&表紙!F44 -> 〒101-0062 東京都千代田区神田駿河台4-6 御茶ノ水ソラシティ アカデミア 4F
A27: １．団体概要 | B27: フリガナ | C27: ='１．団体概要'!D3 -> デジタルハリウッドカブシキガイシャ
B28: 団体名 | C28: ='１．団体概要'!D4 -> デジタルハリウッド株式会社（事業主体：デジタルハリウッド大学・大学院）
B29: 代表者役職名 | C29: ='１．団体概要'!D5 -> 代表取締役社長兼CEO
B30: フリガナ | C30: ='１．団体概要'!N5 -> フジイ マサノリ
B31: 代表者氏名 | C31: ='１．団体概要'!N6 -> 藤井 雅徳
B32: 郵便番号 | C32: ='１．団体概要'!D7&" - "&'１．団体概要'!F7 -> 101 - 0062
B33: 住所 | C33: ='１．団体概要'!D8 -> 東京都千代田区神田駿河台4-6 御茶ノ水ソラシティ アカデミア 4F
B34: 電話 | C34: ='１．団体概要'!N7 -> 03-5289-9230
B35: メールアドレス | C35: ='１．団体概要'!N8 -> fujiimasanori@dhw.co.jp
B36: ウェブサイト | C36: ='１．団体概要'!N9 -> https://www.dhw.ac.jp/
B37: 団体の種類① | C37: ='１．団体概要'!D10 -> その他法人
B38: 団体の種類② | C38: ='１．団体概要'!G10 -> 株式会社
B39: 団体設立年月 | C39: ='１．団体概要'!D11 -> 2005年4月
B40: 法人設立年月 | C40: ='１．団体概要'!J11 -> 1994年10月3日
...

Sheet PPT変更履歴
A1: ②交付要望書パワポ_ver13_沖提案追記.pptx 変更履歴
A3: スライド | B3: 区分 | C3: 変更前 | D3: 変更後／追加内容 | E3: 備考
A4: 全体方針 | B4: タイトル統一 | C4: ページごとにタイトルが異なる | D4: 「デジタルハリウッド大学 AIを活用したクリエイティブ教育体系化事業 ―入門から専門ワークフロー確立まで―」で全ページ統一 | E4: 1ページごとに変えない
A5: P1（表紙） | B5: 文言削除 | C5: VFX-JAPAN等業界団体との事前協議に基づき、 | D5: （削除）
A6: P1 | B6: 文言修正 | C6: 修了生 | D6: 卒業生・修了生
A7: P1 | B7: テキストボックス追加 | C7: ― | D7: プロジェクト名変更案：AIを活用したクリエイティブ教育体系化事業 ―入門から専門ワークフロー確立まで― | E7: 修正履歴ボックス（赤文字・黄背景）
A8: P1 | B8: テキストボックス追加（4点） | C8: ― | D8: ①プロジェクト概要 ②人材ニーズ ③育成概要 ④成果＋持続的基盤 | E8: 水色背景・紺文字、left:790
A9: P2 | B9: 変更案ボックス追加（3点） | C9: ― | D9: 3年×2軸（VP中上級＋ベネッセAI教育研究所×デジハリ共催ゼミ）のロードマップ | E9: 評価指標・長期アウトカム・予算はそのまま
A10: P2 | B10: 設計方針 | C10: ベネッセ企業ゼミ | D10: ベネッセAI教育研究所とデジタルハリウッド大学が共催するゼミ（以下企業ゼミ） | E10: 初級=企業ゼミ、中級=各ゼミ（クリエイティブ）
A11: P3 | B11: 変更案ボックス追加 | C11: ― | D11: 3ページ目修正案反映
A12: P4 | B12: 変更案ボックス追加 | C12: ― | D12: 4ページ目修正案反映
A13: P5 | B13: 事実誤り修正 | C13: 高性能PC 250台 | D13: （削除） | E13: VPと直接関係ないため削除
A14: P5 | B14: 宣言追加 | C14: ― | D14: 本資料はVP（バーチャルプロダクション）に特化した資料である旨を明記
A15: P5 | B15: 変更案ボックス追加 | C15: ― | D15: 5ページ目修正案ボックスをすべて作成
A16: P6以降 | B16: 手をつけず | C16: ― | D16: ― | E16: テンプレ部分のため放置

Sheet コメント一覧
A1: コメント（差し替え文案）一覧
A3: # | B3: シート名 | C3: セル | D3: 種別・タイトル | E3: 差し替え文案・修正提案（要約） | F3: 対応状況
A4: 1 | B4: ３．全体計画、４．観点対応 | C4: B4 | D4: 修正文案（観点①）3階層育成・AIネイティブ教育基軸 | E4: 本事業は、AI・バーチャルプロダクション（VP）・3DCGを統合的に運用し、映像・VFX・3DCG・アニメーション・ゲームの5分野を横断して活躍できる「AIネイティブ・クリエイター」を、3年間で累計810名（入門600名・中級150名・上級60名）育成する。生成AIとリアルタイム制作の標準化により、3DCG制作フローはアニメ・ゲーム・映像で共通基盤化しつつあり、業界別の育成ではAI時代の制作フローに対応できない。デジタルハリウッド大学が有するLEDウォールVP環境・国際的VFX教授陣を活用し、生成AI×バーチャルプロダクション×3DCGを統合した「AIネイティブ・ワークフロー」を中核とする実践型教育プログラムを実施する。入門コースはベネッセAI教育研究所とデジタルハリウッド大学が共催する企業ゼミ（以下「企業ゼミ」）を基盤とし、中級・上級へのシームレスな接続を確保する。ベネッセAI教育研究所と連携し、教育効果のEBPM評価および全国教育機関への展開を行う。 | F4: ✅ 反映待ち
A5: 2 | B5: ３．全体計画、４．観点対応 | C5: B7 | D5: 修正提案：VFX-JAPAN削除・修了生→卒業生・修了生 | E5: 直接成果として、3年間で810名のAIネイティブ・クリエイターを育成し、業界就業率70%以上、卒業生・修了生の修了後3年継続従事率80%以上を実現する。波及効果として、教材公開・FD研修・出前授業・サマースクール等を通じて、全国の大学・専門学校30機関以上、中等教育機関60校以上にモデルを展開し、教員150名以上を育成する。さらに、業界標準コンピテンシーモデル・国産デジタルデザインプラットフォーム要件定義書を策定・公開し、業界団体（CESA等）・関係省庁（経済産業省・文化庁・内閣府）に共有することで、政策・産業界が参照可能な公共財として提供する。本事業は単一大学の取組を超え、AI時代の産業横断型AIネイティブ・クリエイター教育モデルを日本で初めて構築するものであり、コンテンツ産業の国際競争力強化と文化芸術の国際的プレゼンス向上に貢献する。 | F5: ✅ 反映待ち
A6: 3 | B6: ３．全体計画、４．観点対応 | C6: B11 | D6: 修正提案：職種表記・対応明示 | E6: ① マンガ、アニメ、ゲーム、映像、音楽（ポピュラーミュージック関係）等の分野において、海外発信を見据えたコンテンツ制作の高品質化・需要増大に対して必要となる中核的専門人材（アニメーター（原画、動画、背景）、美術、撮影、編集、音響、ゲームプログラマー、ゲームデザイナー、3DCGクリエイター、VFXクリエイター、VPスーパーバイザー、リアルタイムCGエンジニア、サウンドクリエイター、マンガ翻訳者等）を育成・確保するためのプロジェクトであること。 | F6: ✅ 反映待ち
A7: 4 | B7: ３．全体計画、４．観点対応 | C7: B14 | D7: 修正文案（観点①対応・詳細版） | E7: 本事業は募集要領で例示された中核的専門人材（3DCGクリエイター、VFXクリエイター等）を、AI時代の産業横断型制作フローに対応した形へ発展させ、映像・VFX・3DCG・アニメーション・ゲームの5分野にわたる制作中核人材を育成する。入門・中級・上級の3階層で、Claude（生成AI）＋業界標準ツール群（Adobe/Figma/Canva/Blender/Unreal Engine）の体系学習を行う基本技術習得、エカート教授（元Framestore Los Angeles設立メンバー）によるFramestore流ワークフロー継承、AI×LEDウォール統合ワークフロー設計能力の育成、ベネッセAI教育研究所による業界マッチング・3年継続追跡を統合的に実施し、4観点すべてを充足する設計とする。入門コースはベネッセAI教育研究所とデジタルハリウッド大学が共催する企業ゼミを基盤とし、年間200名（前期100名・後期100名）を受け入れる。 | F7: ✅ 反映待ち
A8: 5 | B8: ３．全体計画、４．観点対応 | C8: B17 | D8: 修正文案（観点②対応）就業・定着基盤 | E8: 本学はデジタルハリウッド創設以来30年、累記9万人以上の卒業生・修了生を輩出し、映像・アニメ・VFX・ゲーム・CG等の各産業で第一線で活躍する卒業生・修了生を多数排出してきた実績を有する。本事業ではこの実績基盤の上に、業界横断的な5領域（映像/アニメ/ゲーム/AI制作/XR）の企業群とOJT・インターンシップ・実制作指導の連携を構築し、卒業生・修了生は特定業界に閉じない選択肢を持つ。ベネッセAI教育研究所が卒業生・修了生の3年継続追跡（産業横断的就業状況・継続従事率）を担い、業界就業率70%以上、卒業生・修了生の修了後3年継続従事率80%以上を目標とする。また、フリーランス契約適正化研修、業界標準コンピテンシーモデル策定により、定着の質的基盤も整備する。事業終了後Train the Trainerによる指導者150名育成と卒業生・修了生コミュニティ運営により、人材育成の自走可能な構造を確立する。 | F8: ✅ 反映待ち
A9: 6 | B9: ３．全体計画、４．観点対応 | C9: B20 | D9: 修正提案：出典・根拠確認 | E9: 人材ニーズは公的・業界データで裏付けられている。経産省「エンタメ・クリエイティブ産業戦略」（2025年6月）は、コンテンツ産業の海外売上が2023年時点で細4.5兆円、205033年に20兆円目標を掛げ、「クリエイター・ビジネス人材の不足」を「8つの不足」の一つに明示。帝国データバンク「アニメ制作市場動向調査2025」ではアニメ制作市場が3,621億円と過去最高更新の一方、元請60%が業績悪化、「利益なき繁忙」と分析。CGWORLDもVFXアーティスト・3DCGアニメーター等の慕性的不足を指摘。デロイト分析でもVP人材（LEDキャリブレーション、Unreal Engineオペレーター等）が不足している。本事業は3年間累誈810名（年270名）のAIネイティブクリエイターを直接輩出するとともに、教材公開・FD研修・出前授業を通じ全国90機関校に波及させ、間接的な人材供給基盤の拡大にも貢献する。 | F9: ⚠️ 要確認
A10: 7 | B10: ３．全体計画、４．観点対応 | C10: B23 | D10: 修正提案：VFX-JAPAN削除・協議状況 | E10: 本事業は連携先ベネッセAI教育研究所との2者連携にて補助型応募要件を満たす（同研究所は教育効果のEBPM評価機関であると同時に、教育モデルを全国の教育機関へ展開する社会実装プレイヤー）。事前協議は実施済みであり、令和8年度第1四半期に正式協定を締結する。ベネッセは①受講生事前事後アセスメントの設計・実施、②卒業生・修了生3年継続追跡、③EBPM評価・要因分析、④研究レポート（中間2版・最絈1版）共同編集、⑤全国教育機関への教育モデル展開支援、⑥高大接続設計、⑦オンライン教育プラットフォームによる普及を担当する。さらに事業実施を通じて、業界横断連携（5領域の企業群）、教育波及連携（全国大学30機関以上/中高60校以上）、行政・産業共有（経産省・文化庁・CESA等）へ拡大する。 | F10: ⚠️ 要確認
A11: 8 | B11: ５．プロジェクト詳細 | C11: B5 | D11: 修正文案（実施方針・3階層詳細） | E11: 【実施方针】 産業横断型AIネイティブ・クリエイターの育成を、入門・中級・上級の3階層で実施する。 入門コース（前期100名・後期100名）はベネッセAI教育研究所とデジタルハリウッド大学が共催する企業ゼミを基盤とし。3DCG・AI・VPの基礎を全員が共通基盤として学ぶ。 中級コース（50名/年）は本人の希望と適性に応じて映像・VFX・3DCG・アニメーション・ゲームの5分野いずれかの専門領域に分化する。 上級コース（20名/年）は中級修了者から選抜し、VP・リアルタイムCGの高度専門能力を養成する。 【決定プロセス】 令和8年度第1～第2四半期にカリキュラム共同開発（エカート教授との統合設計）、AI・VPスキル標準の策定、各コース第1期向け教材開発を実施。 第3四半期から入門・中級・上級の同時開講、LEDウォール環境を活用した産業横断型実制作演習の本格稼働、エカート教授による上級指導を開始する。 【AIネイティブワークフロー】 3DCG制作工程を「①企画・開発、②プリプロダクション、③バーチャルプロダクション、④ポストプロダクション、⑤検証・アーカイブ」の5段階に再設計し、各段階でAI・リアルタイム制作・VPを統合的に活用する。 | F11: ✅ 反映待ち
A12: 9 | B12: ５．プロジェクト詳細 | C12: B13 | D12: 修正文案（実施体制・事務局） | E12: 【事務局】 専従事務局をデジタルハリウッド大学内に設置し、専従スタッフ（プログラム・ディレクター、教務担当、広報担当、経理担当）を配置する。年度ごとの執行計画と実績管理を行う。 【実施体制】 中核実施機関：デジタルハリウッド大学（教育設計・運営・成果評価・卒業生・修了生支援）。中核指導者：クリストファー・ハンス・エカート教授（元Framestore Los Angeles設立メンバー、MTV Video Music Award最優秀視覚効果賞受賞、令和8年招趘予定）。 【連携先】 ベネッセAI教育研究所が教育効果測定・卒業生・修了生追跡・EBPM評価・全国教育機関展開支援・高大接続設計・オンライン普及を担当。 【自己負担金確保】 1,500万円は本学自己資金により確実に確保。安定的な財務基盤に裏付け。 | F12: ✅ 反映待ち
A13: 10 | B13: ５．プロジェクト詳細 | C13: B21 | D13: 修正文案（広報・成果発表・モデル展開） | E13: 特設Web・SNS・業界メディア。年次研究会4回×3年・延べ1,500名。教材公開50本以上・FD研修年2回。出前授業年4回・サマースクール年1回 | F13: ✅ 反映待ち
A14: 11 | B14: ７．連携先、８．指導者等 | C14: B22 | D14: 記載文案：髙野良和（准教授） | E14: 映像制作・MV・VJ・広告映像・クリエイター育成。GROUNDRIDDIM プロデューサー。藤井風「きらり」MV（5億回再生）。2014年〜デジハリ大学教員 | F14: 🔵 記入済み
A15: 12 | B15: ７．連携先、８．指導者等 | C15: B23 | D15: 記載文案：ヤーッコ・サーリ（特任准教授） | E15: 3層構成・年度別プログラム実施件数： ・入門コース（前期・後期）×3年＝6コース ・中級コース（5分野）×3年＝15コース ・上級コース×3年＝3コース ・FD研修（年2回）×3年＝6回 ・出前授業（年4回）×3年＝12回 ・サマースクール（年1回）×3年＝3回 ・年次研究会（年4回）×3年＝12回 →、3年間実施プログラム・イベント等合計30件以上 | F15: 🔵 記入済み
... A21: 18 | B21: ９．成果目標 | C21: E24 | D21: 修正文案：モデル展開根拠 | E21: LEDウォール・ベネッセAI教育研究所連携基盤を背景に、産業横断型AIネイティブクリエイター教育モデルを公共財として展開する。「AI環境・大学4ラボ」を削除。「産業横断型3DCG制作中核人材育成モデル」→「AIネイティブクリエイター教育モデル」に統一。 | F21: ✅ 反映待ち
A23: 凡例： | B23: 🔵 記入済み（セルに値を書き込み完了）
B24: ✅ 反映待ち（Excelコメントのみ、セル修正は手動対応）
B25: ⚠️ 要確認（根拠・出典・連携先記名などの追加作業が必要）

Sheet 作業サマリー
A1: 作業サマリー ②交付要望書パワポ_ver13 / Excel 整備記録
A3: 作業日 | B3: 2026年5月15日
A4: 対象ファイル | B4: ②交付要望書パワポ_ver13_沖提案追記.pptx / 申請書Excel
A6: カテゴリ | B6: 対象シート／箇所 | C6: 作業内容 | D6: 結果・確定値
A7: 教員情札記入 | B7: ７．連携先、８．指導者等 | C7: 高野良和（准教授）・ヤーッコ・サーリ（特任准教授）・古岩祥幸（非常勤講師）のB列へ実記入 | D7: B22=高野良和（准教授・GROUNDRIDDIM） B23=ヤーッコ・サーリ（特任准教授・VP/UE5・ASIAGRAPH2021受賞） B24=古岩祥幸（非常勤・3DCG・PPI出身）
A8: 課顧記入（4名） | B8: 課顧欄（D22～D25） | C8: 高野/ヤーッコ/古岩 各500千円、クリス追加250千円を全３年分に記入 | D8: 課顧小計 3,420千円/年（旧１，670から+1,750）
A9: 文言修正（10件） | B9: 全体計画・プロジェクト詳細・成果目標 | C9: 大学降4ラボ削除・５職種→５分野・統括人材削除・PC250台削除 | D9: 全体計画B4/B14/B20、プロジェクト詳細B5/B13、成果目標E14/E24
A10: 軽都算顕書整備 | B10: 全３年分全費目 | C10: 全３年分費目の追加・修正を実施。収支予算書との金額照合完了 | D10: 小計（税込）151,107千円 消費税控除後 144,645千円
A11: 追加費目 | B11: 講期料（全３年） | C11: 課顧以外に追加：消耗品450/会議費1,130/雑役務費2,470/保陶80各年 | D11: SIGGRAPHx2名：600千円/名（JALエコ/4泊/参加費・日当含む） VPスタジオ: 50千円x12回=600千円/年
A12: スケジュール詳細 | B12: ６．スケジュール詳細 | C12: ガントバー（背景色）で３年x４行構成を視覚化。入門/中級/上級/全体の5分野構成 | D12: 入門=山川+企業ゼミ統合行、中級=5分野、上級=VPスペシャリスト、全体=AIUリテラシー研修
A13: PPT変更履歴 | B13: PPT変更履歴シート | C13: PowerPoint側の変更内容（18件）を一覧表化 | D13: P1～P5の全変更内容を記録済み
A14: コメント一覧 | B14: コメント一覧シート | C14: 各シートのセルコメント修正案を一元管理 | D14: 複数シートの修正案コメントを集約記録済み
A16: 次回確認事項
A17: [ ] | B17: 諸謝金・旅費の字数根拠（偐値単価・回数）の再確認
A18: [ ] | B18: 芸文振旅費規程でプレミアムエコノミー区分の可否確認
A19: [ ] | B19: ベネッセAI教育研究所との共催Formal合意（委託貿・決裁書）の有無確認
A20: [ ] | B20: ヤーッコ・サーリの内註e確認書類整備
A21: [ ] | B21: PPT ver13への変更内容の本文反映（修正案ボックスを本文に取り込む）
A22: [ ] | B22: SIGGRAPH登録料公式金額確認（公式サイトにて）
